[2022-02-08 02:47:54,719] {taskinstance.py:851} INFO - Dependencies all met for <TaskInstance: generate_data.generate_data 2022-02-07T00:00:00+00:00 [queued]>
[2022-02-08 02:47:55,311] {taskinstance.py:851} INFO - Dependencies all met for <TaskInstance: generate_data.generate_data 2022-02-07T00:00:00+00:00 [queued]>
[2022-02-08 02:47:55,312] {taskinstance.py:1042} INFO - 
--------------------------------------------------------------------------------
[2022-02-08 02:47:55,312] {taskinstance.py:1043} INFO - Starting attempt 1 of 1
[2022-02-08 02:47:55,313] {taskinstance.py:1044} INFO - 
--------------------------------------------------------------------------------
[2022-02-08 02:47:55,434] {taskinstance.py:1063} INFO - Executing <Task(PythonOperator): generate_data> on 2022-02-07T00:00:00+00:00
[2022-02-08 02:47:55,443] {standard_task_runner.py:52} INFO - Started process 43 to run task
[2022-02-08 02:47:55,468] {standard_task_runner.py:76} INFO - Running: ['airflow', 'tasks', 'run', 'generate_data', 'generate_data', '2022-02-07T00:00:00+00:00', '--job-id', '3', '--pool', 'default_pool', '--raw', '--subdir', 'DAGS_FOLDER/geanrate_data.py', '--cfg-path', '/tmp/tmp2odqf9ju', '--error-file', '/tmp/tmpo5x516dr']
[2022-02-08 02:47:55,469] {standard_task_runner.py:77} INFO - Job 3: Subtask generate_data
[2022-02-08 02:47:56,238] {logging_mixin.py:104} INFO - Running <TaskInstance: generate_data.generate_data 2022-02-07T00:00:00+00:00 [running]> on host 0a426c4a75ea
[2022-02-08 02:48:00,929] {taskinstance.py:1257} INFO - Exporting the following env vars:
AIRFLOW_CTX_DAG_OWNER=airflow
AIRFLOW_CTX_DAG_ID=generate_data
AIRFLOW_CTX_TASK_ID=generate_data
AIRFLOW_CTX_EXECUTION_DATE=2022-02-07T00:00:00+00:00
AIRFLOW_CTX_DAG_RUN_ID=scheduled__2022-02-07T00:00:00+00:00
[2022-02-08 02:48:08,002] {taskinstance.py:1455} ERROR - 'Variable my_iterator does not exist'
Traceback (most recent call last):
  File "/home/airflow/.local/lib/python3.6/site-packages/airflow/models/taskinstance.py", line 1112, in _run_raw_task
    self._prepare_and_execute_task_with_callbacks(context, task)
  File "/home/airflow/.local/lib/python3.6/site-packages/airflow/models/taskinstance.py", line 1285, in _prepare_and_execute_task_with_callbacks
    result = self._execute_task(context, task_copy)
  File "/home/airflow/.local/lib/python3.6/site-packages/airflow/models/taskinstance.py", line 1315, in _execute_task
    result = task_copy.execute(context=context)
  File "/home/airflow/.local/lib/python3.6/site-packages/airflow/operators/python.py", line 117, in execute
    return_value = self.execute_callable()
  File "/home/airflow/.local/lib/python3.6/site-packages/airflow/operators/python.py", line 128, in execute_callable
    return self.python_callable(*self.op_args, **self.op_kwargs)
  File "/opt/airflow/dags/geanrate_data.py", line 21, in generate_data
    n = int(Variable.get('my_iterator'))
  File "/home/airflow/.local/lib/python3.6/site-packages/airflow/models/variable.py", line 128, in get
    raise KeyError(f'Variable {key} does not exist')
KeyError: 'Variable my_iterator does not exist'
[2022-02-08 02:48:11,327] {taskinstance.py:1503} INFO - Marking task as FAILED. dag_id=generate_data, task_id=generate_data, execution_date=20220207T000000, start_date=20220208T024754, end_date=20220208T024811
[2022-02-08 02:48:14,248] {local_task_job.py:146} INFO - Task exited with return code 1
